<?xml version="1.0"?>
<robot name="pan_tilt">

	<material name="white">
    <color rgba="1 1 1 1"/>
  </material>

	<material name="blue">
    <color rgba="0 0 1 1"/>
  </material>

	<material name="yellow">
    <color rgba="1 1 0 1"/>
  </material>


<!-- baza robotului -->
	<link name="base_link">
		
		<!-- baza robotului VIZUAL-->
    <visual>

			<!-- baza robotului GEOMETRIE-->
			<geometry>
				<cylinder length="0.02" radius="0.2"/>
      </geometry>
			<material name="white"/>
			<origin rpy="0 0 0" xyz="0 0 0.01"/>

    </visual>
  
	</link>

<!-- element de tip pan -->
	<link name="pan_link">
		
		<!-- baza robotului VIZUAL-->
    <visual>

			<!-- baza robotului GEOMETRIE-->
			<geometry>
				<cylinder length="0.4" radius="0.04"/>
      </geometry>
			<material name="blue"/>
			<origin rpy="0 0 0" xyz="0 0 0.2"/>
    </visual>
  
	</link>

<!-- element de tip pan -->
	<link name="tilt_link">
		
		<!-- baza robotului VIZUAL-->
    <visual>

			<!-- baza robotului GEOMETRIE-->
			<geometry>
				<cylinder length="0.3" radius="0.05"/>
      </geometry>
			<material name="yellow"/>
			<origin rpy="0 0 0" xyz="0 0 0"/>
    </visual>
  
	</link>


<!--CUPLE: baza robotului & cilindru -->
	<joint name="pan_joint" type="revolute">
    <parent link="base_link"/>
    <child link="pan_link"/>
		
		<origin xyz="0 0 0.02"/>
    <axis xyz="0 0 1" />
		<limit effort="300" velocity="0.1" lower="-3.14" upper="3.14"/>
	</joint>

<!--CUPLE: element pan & element tilt -->
	<joint name="tilt_joint" type="revolute">
    <parent link="pan_link"/>
    <child link="tilt_link"/>

		<origin xyz="0 0 0.42"/>
    <axis xyz="0 1 0" />
		<limit effort="300" velocity="0.1" lower="-3.14" upper="3.14"/>
	</joint>


</robot>
