<?xml version="1.0"?>
<robot name="pan_tilt">

	<!-- definire culori -->
	<material name="white">
		<color rgba="1 1 1 0.3"/>
	</material>

	<material name="blue">
		<color rgba="0 0 1 0.5"/>
	</material>

	<material name="yellow">
		<color rgba="1 1 0 1"/>
	</material>

	<material name="red">
		<color rgba="1 0 0 0.8"/>
	</material>


	<!-- baza robotului -->
	<link name="base_link">

		<!-- baza robotului VIZUAL-->
		<visual>

			<!-- baza robotului GEOMETRIE-->
			<geometry>
				<mesh filename="package://robotel/meshes/baza.STL"/>
				<!-- <box size="1 1 0.05"/> -->
			</geometry>
			<material name="red"/>
			<origin rpy="0 0 0" xyz="0 0 0.025"/>

		</visual>

	</link>


	<!-- element de tip pan -->
	<link name="pan_link">

		<!-- baza robotului VIZUAL-->
		<visual>

			<!-- baza robotului GEOMETRIE-->
			<geometry>
				<mesh filename="package://robotel/meshes/pan_stalp.STL"/>
				<!-- <box size="0.1 0.1 1"/> -->
			</geometry>
			<material name="yellow"/>
			<origin rpy="0 0 0" xyz="0 0 0.5"/>
		</visual>

	</link>

	<!-- element de tip sfera -->
	<link name="sphere_link">

		<!-- baza robotului VIZUAL-->
		<visual>

			<!-- baza robotului GEOMETRIE-->
			<geometry>
				<sphere radius="0.1"/>
			</geometry>
			<material name="white"/>
			<origin rpy="0 0 0" xyz="0 0 0"/>
		</visual>

	</link>

	<!-- element de tip tilt -->
	<link name="tilt_link">

		<!-- baza robotului VIZUAL-->
		<visual>

			<!-- baza robotului GEOMETRIE-->
			<geometry>
				<cylinder length="0.5" radius="0.075"/>
			</geometry>
			<material name="blue"/>
			<origin rpy="0 0 0" xyz="0 0 0"/>
		</visual>

	</link>


	<!--CUPLE: baza robotului & paralelipiped -->
	<joint name="pan_joint" type="revolute">
		<parent link="base_link"/>
		<child link="pan_link"/>

		<origin xyz="0 0 0.05"/>
		<axis xyz="0 0 1" />
		<limit effort="300" velocity="0.1" lower="-3.14" upper="3.14"/>
	</joint>

	<!--CUPLE: paralelipiped & sfera -->
	<joint name="sphere_joint" type="fixed">
		<parent link="pan_link"/>
		<child link="sphere_link"/>

		<origin xyz="0 0 1"/>
	</joint>

	<!--CUPLE: element pan & element tilt -->
	<joint name="tilt_joint" type="revolute">
		<parent link="pan_link"/>
		<child link="tilt_link"/>

		<origin xyz="0 0 1"/>
		<!-- e relativa distanta de la originea link1 la link2 -->
		<axis xyz="0 1 0" />
		<limit effort="300" velocity="0.1" lower="0" upper="3.14"/>
	</joint>

</robot>

